Workbook

Sheet factor F
A1: วิธีคำนวณเทียบอัตราส่วนเพื่อหาค่า FACTOR F
A4: กรณีค่างานอยู่ระหว่างช่วงของค่างานต้นทุนที่กำหนดในตาราง Factor F ให้เทียบอัตราส่วน เพื่อหา Factor F ดังนี้
A5: สูตร | B5: ต้องการหาค่า Factor F ของค่างานต้นทุน | K5: = | O5: A | R5: บาท
A6: สูตร | B6: ค่า Factor F | C6: = | D6: D- | F6: ( | G6: D | H6: - | I6: E | J6: ) | L6: ( | M6: A | N6: - | O6: B | P6: )
H7: ( | I7: C | K7: - | M7: B | N7: )
A9: ค่างานต้นทุน | B9: ค่าวัสดุและค่าแรงงาน | K9: = | N9: ='1.ปร.4'!F18 | R9: บาท
B12: รวมเป็นเงินประมาณ | K12: = | N12: =N9 | R12: บาท
A14: เงื่อนไข | B14: เงินล่วงหน้าจ่าย | E14: 0 | I14: ดอกเบี้ยเงินกู้ | O14: 0.07 | P14: ต่อปี
B15: เงินประกันผลงานหัก | E15: 0 | I15: ภาษีมูลค่าเพิ่ม | O15: 0.07
A17: เมื่อ | B17: ต้องการหาค่า Factor F ของค่างานต้นทุน | H17: = | I17: A | L17: = | N17: =N9 | R17: บาท
B18: ค่างานต้นทุนตัวต่ำกว่าค่างานต้นทุน A | H18: = | I18: B | L18: = | N18: 2000000 | R18: บาท
B19: ค่างานต้นทุนตัวสูงกว่าค่างานต้นทุน A | H19: = | I19: C | L19: = | N19: 5000000 | R19: บาท
B20: ค่า Factor F ของค่างานต้นทุน B | H20: = | I20: D | L20: = | N20: 1.3051
B21: ค่า Factor F ของค่างานต้นทุน C | H21: = | I21: E | L21: = | N21: 1.302
A23: แทนค่าสูตร | B23: ค่า Factor F | C23: = | D23: =N20&"-" | F23: ="("&N20&"-"&N21&")" | J23: x | K23: ="("&TEXT(N17,"#,##0.00")&"-"&TEXT(N18,"#,##0.00")&")"
H24: ="("&TEXT(N19,"#,##0.00")&"-"&TEXT(N18,"#,##0.00")&")"
B26: ค่าFactor F | C26: = | D26: =D23 | E26: =(((N20-N21)*(N17-N18))/(N19-N18)) | N26: =FLOOR(V26,0.0001) | V26: =N20-E26
Q27: =N26

Sheet 1.ปร.4
A1: รายการประมาณการ | G1: แบบ ปร.4
A2: สถานที่ก่อสร้าง
A3: แบบเลขที่ | E3: รายการเลขที่
A4: กอง | B4: - | E4: กรม
A5: ประมาณการโดย | E5: ประมาณการ เมื่อ
A7: ลำดับ | B7: รายการ | D7: ค่าวัสดุ | E7: ค่าแรง | F7: รวมราคาวัสดุ | G7: หมายเหตุ
A8: ที่ | D8: จำนวนเงิน | E8: จำนวนเงิน | F8: และค่าแรงงาน
B10: หมวดงาน
A11: 1 | B11: ='ปร4.อาคาร'!B7 | D11: ='ปร4.อาคาร'!F19 | E11: ='ปร4.อาคาร'!H19 | F11: =E11+D11
A12: 2 | B12: ='ปร4.อาคาร'!B20 | D12: ='ปร4.อาคาร'!F31 | E12: ='ปร4.อาคาร'!H31 | F12: =E12+D12
A13: 3 | B13: ='ปร4.อาคาร'!B32 | D13: ='ปร4.อาคาร'!F96 | E13: ='ปร4.อาคาร'!H96 | F13: =E13+D13
A14: 4 | B14: ='ปร4.อาคาร'!B121 | D14: ='ปร4.อาคาร'!F176 | E14: ='ปร4.อาคาร'!H176 | F14: =E14+D14
B18: รวมเป็นเงินทั้งสิ้น | D18: =SUM(D11:D16) | E18: =SUM(E11:E16) | F18: =SUM(F11:F16)

Sheet ปร4.อาคาร
I1: แบบ ปร.4
A2: รายการปริมาณงานและราคา
A3: งานก่อสร้าง
A4: สถานที่ก่อสร้าง | G4: จังหวัด
A5: เลขที่ | B5: รายการ | C5: จำนวน | D5: หน่วย | E5: ค่าวัสดุสิ่งของ | G5: ค่าแรงงาน | I5: รวมทั้งสิ้น
E6: ราคา/หน่วย | F6: จำนวนเงิน | G6: ราคา/หน่วย | H6: จำนวนเงิน
A7: 1 | B7: หมวดงานเตรียมพื้นที่และงานรื้อถอน
A8: 1.1 | B8: งานรื้อถอนพื้นที่โดยรอบ | F8: =C8*E8 | H8: =C8*G8 | I8: =F8+H8
B9: - งานรื้อถอนสถาปัตย์ผนังก่ออิฐบล็อกและผนังก่ออิฐบล็อกช่องลมบางส่วน | D9: ตร.ม. | F9: =C9*E9 | H9: =C9*G9 | I9: =F9+H9
B10: - งานรื้อถอนท่อน้ำดี - น้ำทิ้ง นอกอาคารที่ไม่ใช้งาน | D10: เหมา | F10: =C10*E10 | H10: =C10*G10 | I10: =F10+H10
B11: - งานรื้อถอนประตูบานไม้ทางขึ้นบันไดชั้น 2 | D11: ชุด | F11: =C11*E11 | H11: =C11*G11 | I11: =F11+H11
B12: - งานรื้อถอนประตูเหล็กทางขึ้นบันไดชั้น 2 | D12: ชุด | F12: =C12*E12 | H12: =C12*G12 | I12: =F12+H12
B13: - งานรื้อถอนผนังก่ออิฐมอญครึ่งแผ่นทางขึ้นบันไดชั้น 2 | D13: ตร.ม. | F13: =C13*E13 | H13: =C13*G13 | I13: =F13+H13
A14: 1.2 | B14: งานรื้อถอนพื้นที่ห้องน้ำ | F14: =C14*E14 | H14: =C14*G14 | I14: =F14+H14
B15: - งานรื้อถอนระบบสุขาภิบาลท่อขนาดต่างๆของห้องน้ำ | D15: ห้อง | F15: =C15*E15 | H15: =C15*G15 | I15: =F15+H15
A16: 1.3 | B16: งานรื้อถอนพื้นที่หลังคา | F16: =C16*E16 | H16: =C16*G16 | I16: =F16+H16
B17: - งานรื้อถอนโครงสร้างหลังคาบางส่วนที่ชำรุด | D17: ตร.ม. | F17: =C17*E17 | H17: =C17*G17 | I17: =F17+H17
F18: =C18*E18 | H18: =C18*G18 | I18: =F18+H18
A19: รวมราคาค่าแรงและค่าวัสดุ 1 | F19: =SUM(F8:F18) | H19: =SUM(H9:H18) | I19: =SUM(I9:I18)
A20: 2 | B20: หมวดงานโครงสร้างหลังคา
B21: - งานติดตั้งโครงหลังคาสำเร็จรูปใหม่ในส่วนที่ชำรุด | D21: ตร.ม. | F21: =C21*E21 | H21: =C21*G21 | I21: =F21+H21
B22: - งานติดตั้งอุปกรณ์แผ่นเพลทและเหล็กฉากยึดโครงหลังคาสำเร็จรูป | D22: เมตร | F22: =C22*E22 | H22: =C22*G22 | I22: =F22+H22
B23: - งานติดตั้งแปเหล็กชุบสังกะสีสำเร็จรูป | D23: ท่อน | F23: =C23*E23 | H23: =C23*G23 | I23: =F23+H23
B24: - หลังคามุงกระเบื้องลอนคู่ ขนาด 0.50x1.20 ม. หนา 5 มม. ตราช้างสีเลือกภายหลัง | D24: ตร.ม. | F24: =C24*E24 | H24: =C24*G24 | I24: =F24+H24
B25: - ตะปูเกลียวยึดแป | D25: กล่อง | F25: =C25*E25 | H25: =C25*G25 | I25: =F25+H25
B26: - เชิงชายสำเร็จรูป หน้า 8" | D26: เมตร | F26: =C26*E26 | H26: =C26*G26 | I26: =F26+H26
B27: - เชิงชายสำเร็จรูป ปิดลอนคู่ | D27: เมตร | F27: =C27*E27 | H27: =C27*G27 | I27: =F27+H27
B28: - ฟอร์ยกันความร้อน | D28: ตร.ม. | F28: =C28*E28 | H28: =C28*G28 | I28: =F28+H28
B29: - ค่าแรงติดตั้งอุปกรณ์ยึดโครงหลังคาและติดตั้งแปสำเร็จรูป | D29: ตร.ม. | F29: =C29*E29 | H29: =C29*G29 | I29: =F29+H29
F30: =C30*E30 | H30: =C30*G30 | I30: =F30+H30
A31: รวมราคาค่าแรงและค่าวัสดุ 2 | F31: =SUM(F21:F30) | H31: =SUM(H21:H30) | I31: =SUM(I21:I30)
A32: 3 | B32: หมวดงานสถาปัตยกรรม
A33: 3.1 | B33: งานพื้น | F33: =C33*E33 | H33: =C33*G33 | I33: =F33+H33
B34: - F1 - พื้น คสล. ปูกระบื้องเซรามิคขนาด 0.30 x 0.30 ม. | D34: ตร.ม. | F34: =C34*E34 | H34: =C34*G34 | I34: =F34+H34
B35: - F2 - พื้น คสล. ปูหินขัดพร้อมเส้นแบ่งแนว | D35: ตร.ม. | F35: =C35*E35 | H35: =C35*G35 | I35: =F35+H35
B36: - F3 - พื้น คสล. ผิวขัดมันเรียบ | D36: ตร.ม. | F36: =C36*E36 | H36: =C36*G36 | I36: =F36+H36
B37: - F4 - พื้น คสล. ปูบล็อกถนนหนา 6 ซม.สีซิเมนต์ | D37: ตร.ม. | F37: =C37*E37 | H37: =C37*G37 | I37: =F37+H37
B38: - F5 - พื้น คสล. ปูหินขัดที่ลูกตั้ง/ลูกนอน/ชานพักบันไดทั้ง 2 ชุด | D38: ตร.ม. | F38: =C38*E38 | H38: =C38*G38 | I38: =F38+H38
B39: - F6 - พื้น คสล. ปูกระบื้องพอร์ชเลนขนาด 0.60 x 0.60 ม. | D39: ตร.ม. | F39: =C39*E39 | H39: =C39*G39 | I39: =F39+H39
B40: - ขอบคัน ค.ส.ลทางเท้ายาว 1.00 ม. | D40: ท่อน | F40: =C40*E40 | H40: =C40*G40 | I40: =F40+H40
...

Sheet ปร4.ครุภัณฑ์
J1: แบบ ปร.4(ข)
A2: รายการปริมาณงานและราคา
A3: งานก่อสร้าง
A4: สถานที่ก่อสร้าง | G4: จังหวัด
A5: เลขที่ | B5: รายการ | D5: จำนวน | E5: หน่วย | F5: ค่าวัสดุสิ่งของ | H5: ค่าแรงงาน | J5: รวมเป็นเงิน
F6: ราคา | G6: จำนวนเงิน | H6: ราคา | I6: จำนวนเงิน
B7: หมวดงานครุภัณฑ์
A8: 1 | B8: งานครุภัณฑ์สร้างกับที่ | G8: =D8*F8 | I8: =D8*H8 | J8: =G8+I8
B9: - กระดานดำขนาด 1.20 x 7.20 ม. | E9: ชุด | G9: =D9*F9 | I9: =D9*H9 | J9: =G9+I9
G10: =D10*F10 | I10: =D10*H10 | J10: =G10+I10
A11: 2 | B11: งานครุภัณฑ์สั่งซื้อ | G11: =D11*F11 | I11: =D11*H11 | J11: =G11+I11
B12: - โต๊ะและเก้าอี้คุณครู ( ตามแบบ ) | E12: ชุด | G12: =D12*F12 | I12: =D12*H12 | J12: =G12+I12
B13: - โต๊ะและเก้าอี้นักเรียนมัธยมศึกษา ( ตามแบบ ) | E13: ชุด | G13: =D13*F13 | I13: =D13*H13 | J13: =G13+I13
G14: =D14*F14 | I14: =D14*H14 | J14: =G14+I14
G15: =D15*F15 | I15: =D15*H15 | J15: =G15+I15
G16: =D16*F16 | I16: =D16*H16 | J16: =G16+I16
A17: รวมราคาค่าแรงและค่าวัสดุ หมวดงาน 1 และ 2 | G17: =SUM(G8:G16) | H17: =SUM(H8:H16) | I17: =SUM(I8:I16) | J17: =SUM(J8:J16)
A18: รวมราคาค่าแรงและค่าวัสดุงานครุภัณฑ์ | G18: =G17 | H18: =H17 | I18: =I17 | J18: =J17

Sheet ปร.5.อาคาร
G1: ปร.5 (ก)
A2: สรุปค่าก่อสร้าง
A3: งานก่อสร้าง
A4: สถานที่ก่อสร้าง | E4: จังหวัด
A5: หน่วยงาน
A6: แบบ ปร.4 (ก) ที่แนบ | F6: จำนวน แผ่น
A7: ประมาณการราคาเมื่อวันที่ | F7: ปรับราคาเมื่อวันที่
A8: ลำดับที่ | B8: รายการ | D8: ค่างานต้นทุน | E8: Factor F | F8: ค่าก่อสร้าง | G8: หมายเหตุ
D9: ( บาท ) | F9: ( บาท )
A10: 1 | B10: ส่วนที่ 1 ค่างานต้นทุน
D12: ='1.ปร.4'!F18 | E12: ='factor F'!N26 | F12: =D12*E12 | J12: =F12-D12
B13: เงื่อนไข
B14: เงินล่วงหน้าจ่าย......... | C14: 0
B15: เงินประกันผลงานหัก........ | C15: 0
B16: ดอกเบี้ยงเงินกู้................ | C16: 0.06
B17: ค่าภาษีมูลค่าเพิ่ม.......... | C17: 0.07
E18: รวมราคาค่าก่อสร้าง
E19: ยอดสุทธิ
A21: คณะกรรมการกำหนดราคากลาง
E22: (….............................................................)
E25: (…...........................................................)
E28: (…...........................................................)

Sheet ปร 5.ครุภัณฑ์
J1: ปร.5 (ช)
A2: สรุปค่าก่อสร้าง
A3: งานก่อสร้าง
A4: สถานที่ก่อสร้าง | H4: จังหวัด
A5: หน่วยงาน
A6: แบบ ปร.4 (ข) ที่แนบ | F6: จำนวน 1 แผ่น
A7: ประมาณการราคาเมื่อวันที่ | F7: ปรับราคาเมื่อวันที่
A8: ลำดับ | B8: รายการ | E8: ค่าวัสดุและค่าแรงงาน | G8: ภาษี | H8: รวมค่าก่อสร้าง | J8: หมายเหตุ
A9: ที่ | E9: รวมเป็นเงิน | H9: รวมเป็นเงิน (บาท)
A10: 1 | B10: ส่วนที่ 2 ครุภัณฑ์จัดซื้อหรือสั่งซื้อ | E10: ='ปร4.ครุภัณฑ์'!J18 | G10: 0.07 | H10: =E10*(1+G10)
E19: รวมค่าครุภัณฑ์จัดซื้อหรือสั่งซื้อ | H19: =H10
G20: ยอดสุทธิ | H20: =H10 | J20: **
A22: คณะกรรมการกำหนดราคากลาง
E23: (.......................................................)
E26: (.......................................................)
E29: (.......................................................)
A30: เห็นชอบ
E32: (.....................)

Sheet ปร.6
F1: แบบ ปร.6
A2: แบบสรุปราคากลางงานก่อสร้างอาคาร
A3: งานก่อสร้าง
A4: สถานที่ก่อสร้าง | E4: จังหวัด
A5: หน่วยงาน
A6: แบบ ปร.4 (ก) (ข) ปร.5 (ก) (ข) ปร.6 และ Factor F ทั้งหมด | F6: จำนวน แผ่น
A7: ประมาณการโดย
A8: ประมาณการราคาเมื่อวันที่ | F8: ปรับราคาเมื่อวันที่
G9: หน่วย : บาท
A10: ลำดับที่ | B10: รายการ | F10: ค่าวัสดุก่อสร้าง | G10: หมายเหตุ
B11: สรุป
A12: 1 | B12: ส่วนที่ 1 ค่าก่อสร้าง | F12: ='ปร.5.อาคาร'!F12
A13: 2 | B13: ส่วนที่ 2 ค่าครุภัณฑ์จัดซื้อหรือสั่งซื้อ | F13: ='ปร 5.ครุภัณฑ์'!H20
A14: 3 | B14: ส่วนที่ 3 ค่าใช้จ่ายพิเศษตามข้อกำหนดและค่าใช้จ่ายอิ่นที่จำเป็นต้องมี
B23: รวมค่าก่อสร้างทั้งโครงการ | F23: =SUM(F12:F13)
B24: ส่วนลด | F24: 0
A25: สรุป | B25: รวมค่าก่อสร้างทั้งโครงการ
B26: =BAHTTEXT(F23)
A28: คณะกรรมการกำหนดราคากลาง
E29: (..............................................................................)
E32: (..............................................................................)
E35: (...............................................................................)
